<?xml version="1.0" encoding="utf-8"?>
<!-- This URDF was automatically created by SolidWorks to URDF Exporter! Originally created by Stephen Brawner (brawner@gmail.com) 
     Commit Version: 1.6.0-4-g7f85cfe  Build Version: 1.6.7995.38578
     For more information, please see http://wiki.ros.org/sw_urdf_exporter -->
<robot name="myrobot">

  <link name="dummy">
  </link>
  <joint name="dummy_joint" type="fixed">
    <parent link="dummy"/>
    <child link="base_link"/>
  </joint>

  <link name="base_link">
    <inertial>
      <origin xyz="-4.34166855418946E-07 -0.00191327346700396 -0.0324098172129575" rpy="0 0 0" />
      <mass value="7.39394474530876" />
      <inertia ixx="0.0954967430019008" ixy="9.32403879526249E-06" ixz="-3.43429397879675E-05" iyy="0.0431069480988158" iyz="0.000300697445255936" izz="0.0570834724716747" />
    </inertial>
    <visual>
      <origin xyz="0 0 0" rpy="0 0 0" />
      <geometry>
        <mesh filename="package://whell_describe/meshes/base_link.STL" />
      </geometry>
      <material name="">
        <color rgba="0.752941176470588 0.752941176470588 0.752941176470588 1" />
      </material>
    </visual>
    <collision>
      <origin xyz="0 0 0" rpy="0 0 0" />
      <geometry>
        <mesh filename="package://whell_describe/meshes/base_link.STL" />
      </geometry>
    </collision>
  </link>
  <link name="leg1_Link">
    <inertial>
      <origin xyz="-0.00296179513632476 0.0278509504142805 -0.00999486258024125" rpy="0 0 0" />
      <mass value="0.107780230252944" />
      <inertia ixx="0.000160570353990171" ixy="7.88850895785892E-06" ixz="-2.83096797302657E-06" iyy="3.94408412392734E-05" iyz="3.5938991497839E-05" izz="0.000126688221874327" />
    </inertial>
    <visual>
      <origin xyz="0 0 0" rpy="0 0 0" />
      <geometry>
        <mesh filename="package://whell_describe/meshes/leg1_Link.STL" />
      </geometry>
      <material name="">
        <color rgba="0.776470588235294 0.756862745098039 0.737254901960784 1" />
      </material>
    </visual>
    <collision>
      <origin xyz="0 0 0" rpy="0 0 0" />
      <geometry>
        <mesh filename="package://whell_describe/meshes/leg1_Link.STL" />
      </geometry>
    </collision>
  </link>
  <joint name="leg1_jonit" type="continuous">
    <origin xyz="-0.10033 0.044715 -0.0010978" rpy="0 0 0" />
    <parent link="base_link" />
    <child link="leg1_Link" />
    <axis xyz="-1 0 0" />
  </joint>
  <link name="shank1_Link">
    <inertial>
      <origin xyz="-0.0145730362591873 -0.0962750743741553 -0.0734807585361268" rpy="0 0 0" />
      <mass value="0.179910472260127" />
      <inertia ixx="0.000891296395453649" ixy="-5.29724283254463E-05" ixz="-4.04305500687684E-05" iyy="0.000362936768598391" iyz="-0.000342657753877328" izz="0.000550360395377295" />
    </inertial>
    <visual>
      <origin xyz="0 0 0" rpy="0 0 0" />
      <geometry>
        <mesh filename="package://whell_describe/meshes/shank1_Link.STL" />
      </geometry>
      <material name="">
        <color rgba="0.776470588235294 0.756862745098039 0.737254901960784 1" />
      </material>
    </visual>
    <collision>
      <origin xyz="0 0 0" rpy="0 0 0" />
      <geometry>
        <mesh filename="package://whell_describe/meshes/shank1_Link.STL" />
      </geometry>
    </collision>
  </link>
  <joint name="shank1_joint" type="continuous">
    <origin xyz="-0.017267 0.089907 -0.032265" rpy="0 0 0" />
    <parent link="leg1_Link" />
    <child link="shank1_Link" />
    <axis xyz="1 0 0" />
  </joint>
  <link name="wheel1_Link">
    <inertial>
      <origin xyz="0.00354162426154082 1.70101779883858E-13 -1.65006897034914E-13" rpy="0 0 0" />
      <mass value="0.410353278347292" />
      <inertia ixx="0.00104917461619554" ixy="-1.1019631800031E-19" ixz="-7.26801751536343E-20" iyy="0.000555030509494792" iyz="6.19713405757342E-22" izz="0.000555005681095352" />
    </inertial>
    <visual>
      <origin xyz="0 0 0" rpy="0 0 0" />
      <geometry>
        <mesh filename="package://whell_describe/meshes/wheel1_Link.STL" />
      </geometry>
      <material name="">
        <color rgba="0.776470588235294 0.756862745098039 0.737254901960784 1" />
      </material>
    </visual>
    <collision>
      <origin xyz="0 0 0" rpy="0 0 0" />
      <geometry>
        <mesh filename="package://whell_describe/meshes/wheel1_Link.STL" />
      </geometry>
    </collision>
  </link>
  <joint name="wheel1_joint" type="continuous">
    <origin xyz="0.004 -0.14309 -0.10921" rpy="0 0 0" />
    <parent link="shank1_Link" />
    <child link="wheel1_Link" />
    <axis xyz="1 0 0" />
  </joint>
  <link name="leg2_Link">
    <inertial>
      <origin xyz="-0.0029617933112704 -0.0288378178749066 -0.00662978583905092" rpy="0 0 0" />
      <mass value="0.107780319038993" />
      <inertia ixx="0.000160570442225836" ixy="-8.16803108751803E-06" ixz="-1.87780614602322E-06" iyy="3.22181545228066E-05" iyz="-2.46836449803152E-05" izz="0.000133910997044132" />
    </inertial>
    <visual>
      <origin xyz="0 0 0" rpy="0 0 0" />
      <geometry>
        <mesh filename="package://whell_describe/meshes/leg2_Link.STL" />
      </geometry>
      <material name="">
        <color rgba="0.776470588235294 0.756862745098039 0.737254901960784 1" />
      </material>
    </visual>
    <collision>
      <origin xyz="0 0 0" rpy="0 0 0" />
      <geometry>
        <mesh filename="package://whell_describe/meshes/leg2_Link.STL" />
      </geometry>
    </collision>
  </link>
  <joint name="leg2_joint" type="continuous">
    <origin xyz="-0.100333438416407 -0.0445308170026693 0.00420002558831606" rpy="0 0 0" />
    <parent link="base_link" />
    <child link="leg2_Link" />
    <axis xyz="-1 0 0" />
  </joint>
  <link name="shank2_Link">
    <inertial>
      <origin xyz="-0.0213519530085939 0.0636903655129619 -0.0618208189053049" rpy="0 0 0" />
      <mass value="0.110969681386475" />
      <inertia ixx="0.00037579886255165" ixy="6.66749816914594E-05" ixz="-6.47178256156085E-05" iyy="0.000212696384697582" iyz="0.00017762634924654" izz="0.000223282036864336" />
    </inertial>
    <visual>
      <origin xyz="0 0 0" rpy="0 0 0" />
      <geometry>
        <mesh filename="package://whell_describe/meshes/shank2_Link.STL" />
      </geometry>
      <material name="">
        <color rgba="0.776470588235294 0.756862745098039 0.737254901960784 1" />
      </material>
    </visual>
    <collision>
      <origin xyz="0 0 0" rpy="0 0 0" />
      <geometry>
        <mesh filename="package://whell_describe/meshes/shank2_Link.STL" />
      </geometry>
    </collision>
  </link>
  <joint name="shank2_joint" type="continuous">
    <origin xyz="-0.017267 -0.093093 -0.021402" rpy="0 0 0" />
    <parent link="leg2_Link" />
    <child link="shank2_Link" />
    <axis xyz="-1 0 0" />
  </joint>
  <link name="leg3_Link">
    <inertial>
      <origin xyz="0.00296179390525861 -0.0295601416673877 0.0013309553174932" rpy="0 0 0" />
      <mass value="0.107780289771901" />
      <inertia ixx="0.000160570408837357" ixy="8.37262272414038E-06" ixz="-3.76962909929157E-07" iyy="2.67721166577225E-05" iyz="5.07941721264572E-06" izz="0.000139357001455259" />
    </inertial>
    <visual>
      <origin xyz="0 0 0" rpy="0 0 0" />
      <geometry>
        <mesh filename="package://whell_describe/meshes/leg3_Link.STL" />
      </geometry>
      <material name="">
        <color rgba="0.776470588235294 0.756862745098039 0.737254901960784 1" />
      </material>
    </visual>
    <collision>
      <origin xyz="0 0 0" rpy="0 0 0" />
      <geometry>
        <mesh filename="package://whell_describe/meshes/leg3_Link.STL" />
      </geometry>
    </collision>
  </link>
  <joint name="leg3_joint" type="continuous">
    <origin xyz="0.10033 -0.044396 0.0027145" rpy="0 0 0" />
    <parent link="base_link" />
    <child link="leg3_Link" />
    <axis xyz="1 0 0" />
  </joint>
  <link name="shank3_Link">
    <inertial>
      <origin xyz="0.0145730362587635 0.0895157621554137 -0.0815796552262889" rpy="0 0 0" />
      <mass value="0.179910472230441" />
      <inertia ixx="0.000891296395451866" ixy="-4.92533225821652E-05" ixz="4.48867213801404E-05" iyy="0.000423764254627717" iyz="0.000353715791667384" izz="0.000489532909345622" />
    </inertial>
    <visual>
      <origin xyz="0 0 0" rpy="0 0 0" />
      <geometry>
        <mesh filename="package://whell_describe/meshes/shank3_Link.STL" />
      </geometry>
      <material name="">
        <color rgba="0.776470588235294 0.756862745098039 0.737254901960784 1" />
      </material>
    </visual>
    <collision>
      <origin xyz="0 0 0" rpy="0 0 0" />
      <geometry>
        <mesh filename="package://whell_describe/meshes/shank3_Link.STL" />
      </geometry>
    </collision>
  </link>
  <joint name="shank3_joint" type="continuous">
    <origin xyz="0.017267 -0.095425 0.0042964" rpy="0 0 0" />
    <parent link="leg3_Link" />
    <child link="shank3_Link" />
    <axis xyz="-1 0 0" />
  </joint>
  <link name="wheel2_Link">
    <inertial>
      <origin xyz="-0.00354162426172276 5.64565755256652E-15 1.04513619980651E-13" rpy="0 0 0" />
      <mass value="0.410353278347293" />
      <inertia ixx="0.00104917461619554" ixy="-9.69772022477507E-19" ixz="-5.84390539877746E-19" iyy="0.000555021546258159" iyz="1.19248986778692E-08" izz="0.000555014644331987" />
    </inertial>
    <visual>
      <origin xyz="0 0 0" rpy="0 0 0" />
      <geometry>
        <mesh filename="package://whell_describe/meshes/wheel2_Link.STL" />
      </geometry>
      <material name="">
        <color rgba="0.776470588235294 0.756862745098039 0.737254901960784 1" />
      </material>
    </visual>
    <collision>
      <origin xyz="0 0 0" rpy="0 0 0" />
      <geometry>
        <mesh filename="package://whell_describe/meshes/wheel2_Link.STL" />
      </geometry>
    </collision>
  </link>
  <joint name="wheel2_joint" type="continuous">
    <origin xyz="-0.004 0.13304 -0.12125" rpy="0 0 0" />
    <parent link="shank3_Link" />
    <child link="wheel2_Link" />
    <axis xyz="-1 0 0" />
  </joint>
  <link name="leg4_Link">
    <inertial>
      <origin xyz="0.00296179368435685 -0.0295100027500215 0.00217561314171924" rpy="0 0 0" />
      <mass value="0.107780300573618" />
      <inertia ixx="0.000160570420389037" ixy="8.35842065384791E-06" ixz="-6.16204483753029E-07" iyy="2.71545097056882E-05" iyz="8.28889239976255E-06" izz="0.000138974619984521" />
    </inertial>
    <visual>
      <origin xyz="0 0 0" rpy="0 0 0" />
      <geometry>
        <mesh filename="package://whell_describe/meshes/leg4_Link.STL" />
      </geometry>
      <material name="">
        <color rgba="0.776470588235294 0.756862745098039 0.737254901960784 1" />
      </material>
    </visual>
    <collision>
      <origin xyz="0 0 0" rpy="0 0 0" />
      <geometry>
        <mesh filename="package://whell_describe/meshes/leg4_Link.STL" />
      </geometry>
    </collision>
  </link>
  <joint name="leg4_joint" type="continuous">
    <origin xyz="0.10033 0.044405 -0.0025569" rpy="3.1416 0 0" />
    <parent link="base_link" />
    <child link="leg4_Link" />
    <axis xyz="1 0 0" />
  </joint>
  <link name="shank4_Link">
    <inertial>
      <origin xyz="0.021351953008594 -0.0722156864155381 -0.0516059196684826" rpy="0 0 0" />
      <mass value="0.110969681386475" />
      <inertia ixx="0.000375798862551649" ixy="7.55998105963495E-05" ixz="5.40242424635914E-05" iyy="0.000160426874959117" iyz="-0.000168124095385926" izz="0.000275551546602801" />
    </inertial>
    <visual>
      <origin xyz="0 0 0" rpy="0 0 0" />
      <geometry>
        <mesh filename="package://whell_describe/meshes/shank4_Link.STL" />
      </geometry>
      <material name="">
        <color rgba="0.776470588235294 0.756862745098039 0.737254901960784 1" />
      </material>
    </visual>
    <collision>
      <origin xyz="0 0 0" rpy="0 0 0" />
      <geometry>
        <mesh filename="package://whell_describe/meshes/shank4_Link.STL" />
      </geometry>
    </collision>
  </link>
  <joint name="shank4_joint" type="continuous">
    <origin xyz="0.017267 -0.095263 0.0070231" rpy="3.1416 0 0" />
    <parent link="leg4_Link" />
    <child link="shank4_Link" />
    <axis xyz="1 0 0" />
  </joint>
  <link name="wheel3_Link">
    <inertial>
      <origin xyz="4.16333634234434E-17 4.29991082774848E-17 2.28699780657182E-16" rpy="0 0 0" />
      <mass value="0.0632598262485194" />
      <inertia ixx="0.00242059945488792" ixy="1.12545694389301E-19" ixz="-3.29679145674681E-19" iyy="0.00121214011620725" iyz="-3.28366439218914E-19" izz="0.00121214011620725" />
    </inertial>
    <visual>
      <origin xyz="0 0 0" rpy="0 0 0" />
      <geometry>
        <mesh filename="package://whell_describe/meshes/wheel3_Link.STL" />
      </geometry>
      <material name="">
        <color rgba="0.298039215686275 0.298039215686275 0.298039215686275 1" />
      </material>
    </visual>
    <collision>
      <origin xyz="0 0 0" rpy="0 0 0" />
      <geometry>
        <mesh filename="package://whell_describe/meshes/wheel3_Link.STL" />
      </geometry>
    </collision>
  </link>
  <joint name="wheel3_joint" type="continuous">
    <origin xyz="-0.068 0 0" rpy="0 0 0" />
    <parent link="base_link" />
    <child link="wheel3_Link" />
    <axis xyz="1 0 0" />
  </joint>
  <link name="wheel4_Link">
    <inertial>
      <origin xyz="-8.32667268468867E-17 6.46818985764433E-17 1.84444746981374E-16" rpy="0 0 0" />
      <mass value="0.0632598262485191" />
      <inertia ixx="0.00242059945488792" ixy="-9.97955053147804E-20" ixz="3.01946215736051E-19" iyy="0.00121214011620725" iyz="-5.23579299129463E-19" izz="0.00121214011620725" />
    </inertial>
    <visual>
      <origin xyz="0 0 0" rpy="0 0 0" />
      <geometry>
        <mesh filename="package://whell_describe/meshes/wheel4_Link.STL" />
      </geometry>
      <material name="">
        <color rgba="0.298039215686275 0.298039215686275 0.298039215686275 1" />
      </material>
    </visual>
    <collision>
      <origin xyz="0 0 0" rpy="0 0 0" />
      <geometry>
        <mesh filename="package://whell_describe/meshes/wheel4_Link.STL" />
      </geometry>
    </collision>
  </link>

  <joint name="wheel4_joint" type="continuous">
    <origin xyz="0.068 0 0" rpy="3.1416 0 0" />
    <parent link="base_link" />
    <child link="wheel4_Link" />
    <axis xyz="1 0 0" />
  </joint>


  <gazebo>
    <plugin name="Myrobot_ClosedLoopPlugin" filename="libpegasus_gazebo_closed_loop_plugin.so">
      <joint>red_green_joint</joint>
      <child>wheel1_Link</child>
      <parent>shank2_Link</parent>
      <position>0.004 -0.14309 -0.10921</position>
      <rotation>0.00 -0.00 0.00</rotation>
    </plugin>
  </gazebo>


  <gazebo>
    <plugin name="Myrobot_ClosedLoopPlugin" filename="libpegasus_gazebo_closed_loop_plugin.so">
      <joint>green_joint</joint>
      <child>wheel2_Link</child>
      <parent>shank4_Link</parent>
      <position>0.004 -0.14309 -0.10921</position>
      <rotation>0.00 -0.00 0.00</rotation>
    </plugin>
  </gazebo>






</robot>